<?xml version="1.0" encoding="utf-8"?>
<!-- This URDF was automatically created by SolidWorks to URDF Exporter! Originally created by Stephen Brawner (brawner@gmail.com) 
     Commit Version: 1.6.0-4-g7f85cfe  Build Version: 1.6.7995.38578
     For more information, please see http://wiki.ros.org/sw_urdf_exporter -->
<robot name="lus2">
  <mujoco>
        <compiler meshdir="../meshes" discardvisual="false" />
  </mujoco>
  
  <!-- <link name="base">
    <inertial>
      <origin xyz="0 0 0" rpy="0 0 0" />
      <mass value="0.0001" />
      <inertia
        ixx="0.0000000"
        ixy="0.0000000"
        ixz="0.0000000"
        iyy="0.0000000"
        iyz="0.0000000"
        izz="0.0000000" />
    </inertial>
    <visual>
      <origin xyz="0 0 0" rpy="0 0 0" />
      <geometry>
        <box size = "0.001 0.001 0.001"/>
      </geometry>
      <material name="a">
        <color rgba="0.05 0.05 0.05 1" />
      </material>
    </visual>
    <collision>
      <origin xyz="0 0 0" rpy="0 0 0" />
      <geometry>
        <box size = "0.001 0.001 0.001"/>
      </geometry>
    </collision>
  </link>

  <joint name="floating_base_joint" type="fixed">
    <origin xyz="0 0 0" rpy="0 0 0" />
    <parent link="base" />
    <child link="pelvis" />
  </joint> -->

  <link name="pelvis">
    <inertial>
      <origin xyz="-3.1659855E-03  0.0000000 -0.0930236E-01" rpy="0 0 0" />
      <mass value="6.7964049" />
      <inertia
        ixx="3.9641975E-02"
        ixy="0.0000000"
        ixz="1.2568204E-03"
        iyy="3.5762219E-02"
        iyz="0.0000000"
        izz="2.2011165E-02" />
    </inertial>
    <visual>
      <origin xyz="0 0 0.1" rpy="0 0 0" />
      <geometry>
        <mesh filename="../meshes/pelvis.STL" />
      </geometry>
      <material name="a">
        <color rgba="0.05 0.05 0.05 1" />
      </material>
    </visual>
    <!-- <collision>
      <origin xyz="0 0 0" rpy="0 0 0" />
      <geometry>
        <mesh filename="../meshes/pelvis.STL" />
      </geometry>
    </collision> -->
    <collision>
      <origin xyz="0 0 0.0" rpy="0 0 0" />
      <geometry>
        <cylinder radius="0.0572" length="0.1883" />
      </geometry>
    </collision>
  </link>

  <link name="left_hip_pitch_link">
    <inertial>
      <origin xyz="-2.0168256E-02  8.2216101E-02  0.0000000" rpy="0 0 0" />
      <mass value="2.4277335" />
      <inertia
        ixx="6.1432167E-03"
        ixy="4.8775061E-04"
        ixz="0.0000000"
        iyy="3.6201357E-03"
        iyz="0.0000000"
        izz="5.1618570E-03" />
    </inertial>
    <visual>
      <origin xyz="0 0 0.0" rpy="0 0 0" />
      <geometry>
        <mesh filename="../meshes/left_hip_pitch_link.STL" />
      </geometry>
      <material name="a">
        <color rgba="0.05 0.05 0.05 1" />
      </material>
    </visual>
    <collision>
      <origin xyz="0 0 0" rpy="0 0 0" />
      <geometry>
        <mesh filename="../meshes/left_hip_pitch_link.STL" />
      </geometry>
    </collision>
    <!-- <collision>
      <origin xyz="0 0.01 0" rpy="1.57 0 0" />
      <geometry>
        <cylinder radius="0.045" length="0.0234" />
      </geometry>
    </collision> -->
  </link>

  <joint name="left_hip_pitch_joint" type="revolute">
    <origin xyz="0 0.068 -0.056" rpy="0 0 0" />
    <parent link="pelvis" />
    <child link="left_hip_pitch_link" />
    <axis xyz="0 1 0" />
    <limit lower="-1.5" upper="1.5" effort="300" velocity="11" />
  </joint>

  <link name="left_hip_roll_link">
    <inertial>
      <origin xyz="-2.3116200E-03 -3.6364046E-04 -8.1422005E-02" rpy="0 0 0" />
      <mass value="3.1551632" />
      <inertia
        ixx="1.2134241E-02"
        ixy="-4.1927788E-05"
        ixz="-1.9137034E-03"
        iyy="1.1479866E-02"
        iyz="-1.2177975E-04"
        izz="7.1752202E-03" />
    </inertial>
    <visual>
      <origin xyz="0 0 0" rpy="0 0 0" />
      <geometry>
        <mesh filename="../meshes/left_hip_roll_link.STL" />
      </geometry>
      <material name="a">
        <color rgba="0.05 0.05 0.05 1" />
      </material>
    </visual>
    <collision>
      <origin xyz="0 0 0" rpy="0 0 0" />
      <geometry>
        <mesh filename="../meshes/left_hip_roll_link.STL" />
      </geometry>
    </collision>
    <!-- <collision>
      <origin xyz="-0.01 0 0" rpy="0 1.57 0" />
      <geometry>
        <cylinder radius="0.065" length="0.13" />
      </geometry>
    </collision> -->
  </link>

  <joint name="left_hip_roll_joint" type="revolute">
    <origin xyz="0 0.092 0" rpy="0 0 0" />
    <parent link="left_hip_pitch_link" />
    <child link="left_hip_roll_link" />
    <axis xyz="1 0 0" />
    <limit lower="-0.25" upper="2.8" effort="300" velocity="11" />
  </joint>

  <link name="left_hip_yaw_link">
    <inertial>
      <origin xyz="6.4280485E-03 -3.5846370E-03 -1.8449587E-01" rpy="0 0 0" />
      <mass value="3.3522325" />
      <inertia
        ixx="3.8105084E-02"
        ixy="-7.7153373E-05"
        ixz="-7.3176284E-04"
        iyy="3.9597910E-02"
        iyz="-9.0739735E-04"
        izz="7.1960830E-03" />
    </inertial>
    <visual>
      <origin xyz="0 0 0" rpy="0 0 0" />
      <geometry>
        <mesh filename="../meshes/left_hip_yaw_link.STL" />
      </geometry>
      <material name="a">
        <color rgba="0.05 0.05 0.05 1" />
      </material>
    </visual>
    <collision>
      <origin xyz="0 0 0" rpy="0 0 0" />
      <geometry>
        <mesh filename="../meshes/left_hip_yaw_link.STL" />
      </geometry>
    </collision> 

    <!-- <collision>
      <origin xyz="0 0 0" rpy="0 0 0" />
      <geometry>
        <cylinder radius="0.0708" length="0.142" />
      </geometry>
    </collision> -->
  </link>

  <joint name="left_hip_yaw_joint" type="revolute">
    <origin xyz="0 0 -0.1395" rpy="0 0 0" />
    <parent link="left_hip_roll_link" />
    <child link="left_hip_yaw_link" />
    <axis xyz="0 0 1" />
    <limit lower="-1.2" upper="2.6" effort="300" velocity="11" />
  </joint>

  <link name="left_knee_link">
    <inertial>
      <origin xyz="9.7804057e-03 -1.2159820e-03 -1.1000733e-01" rpy="0 0 0" />
      <mass value="5.3828222" />
      <inertia
        ixx="7.1014736e-02"
        ixy="-6.3321397e-05"
        ixz="9.4868042e-04"
        iyy="7.2059618e-02"
        iyz="1.0601703e-03"
        izz="8.1731788e-03" />
    </inertial>
    <visual>
      <origin xyz="0 0 0" rpy="0 0 0" />
      <geometry>
        <mesh filename="../meshes/left_knee_link_v1.STL" />
      </geometry>
      <material name="a">
        <color rgba="0.05 0.05 0.05 1" />
      </material>
    </visual>
    <collision>
      <origin xyz="0 0 0" rpy="0 0 0" />
      <geometry>
        <mesh filename="../meshes/left_knee_link.STL" />
      </geometry>
    </collision> 
    <!--
    <collision>
      <origin xyz="0 0 -0.13" rpy="0 0 0" />
      <geometry>
        <box size = "0.109 0.095 0.278"/>
      </geometry>
    </collision> -->
  </link>

  <joint name="left_knee_joint" type="revolute">
    <origin xyz="0 0 -0.26" rpy="0 0 0" />
    <parent link="left_hip_yaw_link" />
    <child link="left_knee_link" />
    <axis xyz="0 1 0" />
    <limit lower="0.0" upper="2.27" effort="300" velocity="11" />
  </joint>

  <link name="left_ankle_pitch_link">
    <inertial>
      <origin xyz="-3.1002626e-04  1.1061714e-05 -4.2515953e-03" rpy="0 0 0" />
      <mass value="1.6375855e-01" />
      <inertia
        ixx="5.5690573e-05"
        ixy="-2.3322493e-10"
        ixz="-3.1117387e-07"
        iyy="2.3118959e-05"
        iyz="4.0748259e-10"
        izz="5.5144716e-05" />
    </inertial>
    <visual>
      <origin xyz="0 0 0" rpy="0 0 0" />
      <geometry>
        <mesh filename="../meshes/left_ankle_pitch_link.STL" />
      </geometry>
      <material name="a">
        <color rgba="0.05 0.05 0.05 1" />
      </material>
    </visual>
    <collision>
      <origin xyz="0 0 0" rpy="0 0 0" />
      <geometry>
        <mesh filename="../meshes/left_ankle_pitch_link.STL" />
      </geometry>
    </collision>
    <!-- <collision>
      <origin xyz="0 0 0" rpy="1.57 0 0" />
      <geometry>
        <cylinder radius="0.009" length="0.032" />
      </geometry>
    </collision> -->
  </link>

  <joint name="left_ankle_pitch_joint" type="revolute">
    <origin xyz="0 0 -0.4" rpy="0 0 0" />
    <parent link="left_knee_link" />
    <child link="left_ankle_pitch_link" />
    <axis xyz="0 1 0" />
    <limit lower="-1.0" upper="0.43" effort="100" velocity="14" />
  </joint>

  <link name="left_ankle_roll_link">
    <inertial>
      <origin xyz="1.7804206e-02  0.0000000e+00 -2.2944985e-02" rpy="0 0 0" />
      <mass value="3.2840177e-01" />
      <inertia
        ixx="2.3276192e-04"
        ixy="0.0000000"
        ixz="9.9000753e-05"
        iyy="1.3849144e-03"
        iyz="0.0000000"
        izz="1.4703900e-03" />
    </inertial>
    <visual>
      <origin xyz="0 0 0" rpy="0 0 0" />
      <geometry>
        <mesh filename="../meshes/left_ankle_roll_link_v1.STL" />
      </geometry>
      <material name="a">
        <color rgba="0.05 0.05 0.05 1" />
      </material>
    </visual>
    <!-- <collision>
      <origin xyz="0 0 0" rpy="0 0 0" />
      <geometry>
        <mesh filename="../meshes/left_ankle_roll_link.STL" />
      </geometry>
    </collision> -->


    <collision>
      <origin xyz="0.025 0 -0.03385" rpy="0 0 0" />
      <geometry>
        <box size = "0.235 0.073 0.0143"/>
      </geometry>
    </collision>

   <collision>
      <origin xyz="-0.085 0.035 -0.04" rpy="0 0 0"/>
      <geometry>
        <sphere radius="0.005"/>
      </geometry>
    </collision>
    <collision>
      <origin xyz="-0.085 -0.035 -0.04" rpy="0 0 0"/>
      <geometry>
        <sphere radius="0.005"/>
      </geometry>
    </collision>
    <collision>
      <origin xyz="0.135 0.035 -0.04" rpy="0 0 0"/>
      <geometry>
        <sphere radius="0.005"/>
      </geometry>
    </collision>
    <collision>
      <origin xyz="0.135 -0.035 -0.04" rpy="0 0 0"/>
      <geometry>
        <sphere radius="0.005"/>
      </geometry>
    </collision>
    <collision>
      <origin xyz="0.05 -0.045 -0.04" rpy="0 0 0"/>
      <geometry>
        <sphere radius="0.005"/>
      </geometry>
    </collision>
    <collision>
      <origin xyz="0.05 0.045 -0.04" rpy="0 0 0"/>
      <geometry>
        <sphere radius="0.005"/>
      </geometry>
    </collision>
    <collision>
      <origin xyz="0.145 -0.0 -0.04" rpy="0 0 0"/>
      <geometry>
        <sphere radius="0.005"/>
      </geometry>
    </collision>
    <collision>
      <origin xyz="-0.09 -0.0 -0.04" rpy="0 0 0"/>
      <geometry>
        <sphere radius="0.005"/>
      </geometry>
    </collision>
 

  </link>

  <joint name="left_ankle_roll_joint" type="revolute">
    <origin xyz="0 0 -0.01" rpy="0 0 0" />
    <parent link="left_ankle_pitch_link" />
    <child link="left_ankle_roll_link" />
    <axis xyz="1 0 0" />
    <limit lower="-0.43" upper="0.43" effort="100" velocity="14" />
  </joint>

  <link name="right_hip_pitch_link">
    <inertial>
      <origin xyz="-2.0168256E-02 -8.2216101E-02  0.0000000" rpy="0 0 0" />
      <mass value="2.4277335" />
      <inertia
        ixx="6.1432167E-03"
        ixy="-4.8775061E-04"
        ixz="0.0000000"
        iyy="3.6201357E-03"
        iyz="0.0000000"
        izz="5.1618570E-03" />
    </inertial>
    <visual>
      <origin xyz="0 0 0" rpy="0 0 0" />
      <geometry>
        <mesh filename="../meshes/right_hip_pitch_link.STL" />
      </geometry>
      <material name="a">
        <color rgba="0.05 0.05 0.05 1" />
      </material>
    </visual>
    <collision>
      <origin xyz="0 0 0"  rpy="0 0 0" />
      <geometry>
        <mesh filename="../meshes/right_hip_pitch_link.STL" />
      </geometry>
    </collision>
    <!-- <collision>
      <origin xyz="0 -0.01 0" rpy="1.57 0 0" />
      <geometry>
        <cylinder radius="0.045" length="0.0234" />
      </geometry>
    </collision> -->
  </link>

  <joint name="right_hip_pitch_joint" type="revolute">
    <origin xyz="0 -0.068 -0.056" rpy="0 0 0" />
    <parent link="pelvis" />
    <child link="right_hip_pitch_link" />
    <axis xyz="0 1 0" />
    <limit lower="-1.5" upper="1.5" effort="300" velocity="11" />
  </joint>

  <link name="right_hip_roll_link">
    <inertial>
      <origin xyz="-2.3116409E-03  3.6367554E-04 -8.1422055E-02" rpy="0 0 0" />
      <mass value="3.1551628" />
      <inertia
        ixx="1.2134227E-02"
        ixy="4.1929406E-05"
        ixz="-1.9137018E-03"
        iyy="1.1479853E-02"
        iyz="1.2177538E-04"
        izz="7.1752213E-03" />
    </inertial>
    <visual>
      <origin xyz="0 0 0" rpy="0 0 0" />
      <geometry>
        <mesh filename="../meshes/right_hip_roll_link.STL" />
      </geometry>
      <material name="a">
        <color rgba="0.05 0.05 0.05 1" />
      </material>
    </visual>
    <collision>
      <origin xyz="0 0 0" rpy="0 0 0" />
      <geometry>
        <mesh filename="../meshes/right_hip_roll_link.STL" />
      </geometry>
    </collision>
    <!-- <collision>
      <origin xyz="-0.01 0 0" rpy="0 1.57 0" />
      <geometry>
        <cylinder radius="0.065" length="0.13" />
      </geometry>
    </collision> -->
  </link>

  <joint name="right_hip_roll_joint" type="revolute">
    <origin  xyz="0 -0.092 0" rpy="0 0 0" />
    <parent link="right_hip_pitch_link" />
    <child link="right_hip_roll_link" />
    <axis xyz="1 0 0" />
    <limit lower="-2.8" upper="0.25" effort="300" velocity="11" />
  </joint>

  <link name="right_hip_yaw_link">
    <inertial>
      <origin xyz="6.4280485E-03  3.5846369E-03 -1.8449587E-01" rpy="0 0 0" />
      <mass value="3.3522326" />
      <inertia
        ixx="3.8105084E-02"
        ixy="7.7153371E-05"
        ixz="-7.3176284E-04"
        iyy="3.9597910E-02"
        iyz="9.0739735E-04"
        izz="7.1960830E-03" />
    </inertial>
    <visual>
      <origin xyz="0 0 0" rpy="0 0 0" />
      <geometry>
        <mesh filename="../meshes/right_hip_yaw_link.STL" />
      </geometry>
      <material name="a">
        <color rgba="0.05 0.05 0.05 1" />
      </material>
    </visual>
    <collision>
      <origin xyz="0 0 0" rpy="0 0 0" />
      <geometry>
        <mesh filename="../meshes/right_hip_yaw_link.STL" />
      </geometry>
    </collision>
    <!-- <collision>
      <origin xyz="0 0 0" rpy="0 0 0" />
      <geometry>
        <cylinder radius="0.0708" length="0.142" />
      </geometry>
    </collision> -->
  </link>

  <joint name="right_hip_yaw_joint" type="revolute">
    <origin xyz="0 0 -0.1395" rpy="0 0 0" />
    <parent link="right_hip_roll_link" />
    <child link="right_hip_yaw_link" />
    <axis xyz="0 0 1" />
    <limit lower="-2.6" upper="1.2" effort="300" velocity="11" />
  </joint>

  <link name="right_knee_link">
    <inertial>
      <origin xyz="9.7804052e-03  1.2159799e-03 -1.1000734e-01" rpy="0 0 0" />
      <mass value="5.3828227" />
      <inertia
        ixx="7.1014747e-02"
        ixy="6.3321335e-05"
        ixz="9.4868006e-04"
        iyy="7.2059629e-02"
        iyz="-1.0601720e-03"
        izz="8.1731791e-03" />
    </inertial>
    <visual>
      <origin xyz="0 0.0 0" rpy="0 0 0" />
      <geometry>
        <mesh filename="../meshes/right_knee_link_v1.STL" />
      </geometry>
      <material name="a">
        <color rgba="0.05 0.05 0.05 1" />
      </material>
    </visual>
    <collision>
      <origin xyz="0 0 0" rpy="0 0 0" />
      <geometry>
        <mesh filename="../meshes/right_knee_link.STL" />
      </geometry>
    </collision>
    <!-- <collision>
      <origin xyz="0 0 -0.13" rpy="0 0 0" />
      <geometry>
        <box size = "0.109 0.095 0.278"/>
      </geometry>
    </collision> -->
  </link>

  <joint name="right_knee_joint" type="revolute">
    <origin xyz="0 0 -0.26" rpy="0 0 0" />
    <parent link="right_hip_yaw_link" />
    <child link="right_knee_link" />
    <axis xyz="0 1 0" />
    <limit lower="0.0" upper="2.27" effort="300" velocity="11" />
  </joint>

  <link name="right_ankle_pitch_link">
    <inertial>
      <origin xyz="-3.1002626e-04  1.1061714e-05 -4.2515953e-03" rpy="0 0 0" />
      <mass value="1.6375855e-01" />
      <inertia
        ixx="5.5690573e-05"
        ixy="-2.3322493e-10"
        ixz="-3.1117387e-07"
        iyy="2.3118959e-05"
        iyz="4.0748259e-10"
        izz="5.5144716e-05" />
    </inertial>
    <visual>
      <origin xyz="0 0 0" rpy="0 0 0" />
      <geometry>
        <mesh filename="../meshes/right_ankle_pitch_link.STL" />
      </geometry>
      <material name="a">
        <color rgba="0.05 0.05 0.05 1" />
      </material>
    </visual>
    <!-- <collision>
      <origin xyz="0 0 0" rpy="0 0 0" />
      <geometry>
        <mesh filename="../meshes/right_ankle_pitch_link.STL" />
      </geometry>
    </collision> -->
    <collision>
      <origin xyz="0 0 0" rpy="1.57 0 0" />
      <geometry>
        <cylinder radius="0.009" length="0.032" />
      </geometry>
    </collision>
  </link>

  <joint name="right_ankle_pitch_joint" type="revolute">
    <origin xyz="0 0 -0.4" rpy="0 0 0" />
    <parent link="right_knee_link" />
    <child link="right_ankle_pitch_link" />
    <axis xyz="0 1 0" />
    <limit lower="-1.0" upper="0.43" effort="100" velocity="14" />
  </joint>

  <link name="right_ankle_roll_link">
    <inertial>
      <origin xyz="1.7804206e-02  0.0000000e+00 -2.2944985e-02" rpy="0 0 0" />
      <mass value="3.2840177e-01" />
      <inertia
        ixx="2.3276192e-04"
        ixy="0.0000000"
        ixz="9.9000753e-05"
        iyy="1.3849144e-03"
        iyz="0.0000000"
        izz="1.4703900e-03" />
    </inertial>
    <visual>
      <origin xyz="-0.00 0.00 0" rpy="0 0 0" />
      <geometry>
        <mesh filename="../meshes/right_ankle_roll_link_v1.STL" />
      </geometry>
      <material name="a">
        <color rgba="0.05 0.05 0.05 1" />
      </material>
    </visual>
    <!-- <collision>
      <origin xyz="0 0 0" rpy="0 0 0" />
      <geometry>
        <mesh filename="../meshes/right_ankle_roll_link.STL" />
      </geometry>
    </collision> -->
    
    <collision>
      <origin xyz="0.025 0 -0.03385" rpy="0 0 0" />
      <geometry>
        <box size = "0.235 0.073 0.0143"/>
      </geometry>
    </collision>
    


   <collision>
      <origin xyz="-0.085 0.035 -0.04" rpy="0 0 0"/>
      <geometry>
        <sphere radius="0.005"/>
      </geometry>
    </collision>
    <collision>
      <origin xyz="-0.085 -0.035 -0.04" rpy="0 0 0"/>
      <geometry>
        <sphere radius="0.005"/>
      </geometry>
    </collision>
    <collision>
      <origin xyz="0.135 0.035 -0.04" rpy="0 0 0"/>
      <geometry>
        <sphere radius="0.005"/>
      </geometry>
    </collision>
    <collision>
      <origin xyz="0.135 -0.035 -0.04" rpy="0 0 0"/>
      <geometry>
        <sphere radius="0.005"/>
      </geometry>
    </collision>
    <collision>
      <origin xyz="0.05 -0.045 -0.04" rpy="0 0 0"/>
      <geometry>
        <sphere radius="0.005"/>
      </geometry>
    </collision>
    <collision>
      <origin xyz="0.05 0.045 -0.04" rpy="0 0 0"/>
      <geometry>
        <sphere radius="0.005"/>
      </geometry>
    </collision>
    <collision>
      <origin xyz="0.145 -0.0 -0.04" rpy="0 0 0"/>
      <geometry>
        <sphere radius="0.005"/>
      </geometry>
    </collision>
    <collision>
      <origin xyz="-0.09 -0.0 -0.04" rpy="0 0 0"/>
      <geometry>
        <sphere radius="0.005"/>
      </geometry>
    </collision>

  </link>

  <joint name="right_ankle_roll_joint" type="revolute">
    <origin xyz="0 0 -0.01" rpy="0 0 0" />
    <parent link="right_ankle_pitch_link" />
    <child link="right_ankle_roll_link" />
    <axis xyz="1 0 0" />
    <limit lower="-0.43" upper="0.43" effort="100" velocity="14" />
  </joint>

  <link name="torso_link">
    <inertial>
      <origin xyz="-2.3606484E-03  2.8289136E-04  2.3074545E-01" rpy="0 0 0" />
      <mass value="1.0563174E+01" />
      <inertia
        ixx="1.3744844E-01"
        ixy="1.3568744E-04"
        ixz="5.7196351E-03"
        iyy="1.1331419E-01"
        iyz="-4.6372000E-04"
        izz="6.5891007E-02" />
    </inertial>
    <visual>
      <origin xyz="0 0 0" rpy="0 0 0" />
      <geometry>
        <mesh filename="../meshes/torso_link.STL" />
      </geometry>
      <material name="a">
        <color rgba="0.05 0.05 0.05 1" />
      </material>
    </visual>
    <collision>
      <origin xyz="0 0 0" rpy="0 0 0" />
      <geometry>
        <mesh filename="../meshes/torso_link.STL" />
      </geometry>
    </collision>
    <!-- <collision>
      <origin xyz="0.0065 0.0 0.21" rpy="0 0 0" />
      <geometry>
        <box size = "0.205 0.178 0.246"/>
      </geometry>
    </collision> -->
  </link>

  <joint name="torso_joint" type="revolute">
    <origin xyz="0 0 0.1" rpy="0 0 0" />
    <parent link="pelvis" />
    <child link="torso_link" />
    <axis xyz="0 0 1" />
    <limit lower="-3" upper="3" effort="300" velocity="11" />
  </joint>

  <link name="head_link">
    <inertial>
      <origin xyz="0.00822737744778477 -0.000198850473705812 0.107120349130616" rpy="0 0 0" />
      <mass value="1.02775179782002" />
      <inertia
        ixx="0.00169703133506373"
        ixy="2.89967965428031E-07"
        ixz="0.000184215223504519"
        iyy="0.00191732132579063"
        iyz="1.69965812692335E-07"
        izz="0.00219567889747987" />
    </inertial>
    <visual>
      <origin xyz="0 0 0" rpy="0 0 0" />
      <geometry>
        <mesh filename="../meshes/head_link.STL" />
      </geometry>
      <material name="a">
        <color rgba="0.05 0.05 0.05 1" />
      </material>
    </visual>
    <!-- <collision>
      <origin xyz="0 0 0" rpy="0 0 0" />
      <geometry>
        <mesh filename="../meshes/head_link.STL" />
      </geometry>
    </collision> -->
    <collision>
      <origin xyz="0 0 0.11" rpy="0 0 0" />
      <geometry>
        <sphere radius="0.08" />
      </geometry>
    </collision>
  </link>

  <joint name="head_joint" type="revolute">
    <origin xyz="0 0 0.3875" rpy="0 0 0" />
    <parent link="torso_link" />
    <child link="head_link" />
    <axis xyz="0 0 1" />
    <limit lower="-1.3" upper="1.3" effort="17" velocity="87" />
  </joint>

  <link name="left_shoulder_pitch_link">
    <inertial>
      <origin xyz="-1.9833474e-02 4.4431912e-02 -5.5587489e-06" rpy="0 0 0" />
      <mass value="3.0353084e-01" />
      <inertia
        ixx="3.9643671e-04"
        ixy="9.9021623e-05"
        ixz="2.2578362e-09"
        iyy="1.6487917e-04"
        iyz="-2.0641827e-08"
        izz="3.8208098e-04" />
    </inertial>
    <visual>
      <origin xyz="0 0 0" rpy="0 0 0" />
      <geometry>
        <mesh filename="../meshes/left_shoulder_pitch_link.STL" />
      </geometry>
      <material name="a">
        <color rgba="0.05 0.05 0.05 1" />
      </material>
    </visual>
    <!-- <collision>
      <origin xyz="0 0 0" rpy="0 0 0" />
      <geometry>
        <mesh filename="../meshes/left_shoulder_pitch_link.STL" />
      </geometry>
    </collision> -->
    <collision>
      <origin xyz="0 0.01 0" rpy="1.57 0 0" />
      <geometry>
        <cylinder radius="0.0244" length="0.018" />
      </geometry>
    </collision>
  </link>

  <joint name="left_shoulder_pitch_joint" type="revolute">
    <origin xyz="0 0.12095 0.29712" rpy="-0.17453 0 0" />
    <parent link="torso_link" />
    <child link="left_shoulder_pitch_link" />
    <axis xyz="0 1 0" />
    <limit lower="-3" upper="3" effort="100" velocity="14" />
  </joint>

  <link name="left_shoulder_roll_link">
    <inertial>
      <origin xyz="4.6571984e-03 -4.1483153e-05 -5.5419414e-02" rpy="0 0 0" />
      <mass value="1.6480208e+00" />
      <inertia
        ixx="5.2969146e-03"
        ixy="2.4490248e-06"
        ixz="-4.4137516e-04"
        iyy="5.2914384e-03"
        iyz="3.7517169e-06"
        izz="1.2519989e-03" />
    </inertial>
    <visual>
      <origin xyz="0 0 0" rpy="0 0 0" />
      <geometry>
        <mesh filename="../meshes/left_shoulder_roll_link.STL" />
      </geometry>
      <material name="a">
        <color rgba="0.05 0.05 0.05 1" />
      </material>
    </visual>
    <!-- <collision>
      <origin xyz="0 0 0" rpy="0 0 0" />
      <geometry>
        <mesh filename="../meshes/left_shoulder_roll_link.STL" />
      </geometry>
    </collision> -->
    <collision>
      <origin xyz="0 0 0" rpy="0 1.57 0" />
      <geometry>
        <cylinder radius="0.0447" length="0.1" />
      </geometry>
    </collision>
  </link>

  <joint name="left_shoulder_roll_joint" type="revolute">
    <origin xyz="0 0.0695 0" rpy="0.17453 0 0" />
    <parent link="left_shoulder_pitch_link" />
    <child link="left_shoulder_roll_link" />
    <axis xyz="1 0 0" />
    <limit lower="-0.12" upper="2.3" effort="100" velocity="14" />
  </joint>

  <link name="left_shoulder_yaw_link">
    <inertial>
      <origin xyz="-8.6588242e-04 2.7056403e-03 -1.1851791e-01" rpy="0 0 0"/>
      <mass value="1.0475838e+00"/>
      <inertia
        ixx="2.6989882e-03" 
        ixy="-2.9561127e-06" 
        ixz="4.3512567e-05" 
        iyy="2.7131219e-03" 
        iyz="6.1012281e-05" 
        izz="7.9314932e-04"/>
    </inertial>
    <visual>
      <origin xyz="0 0 0" rpy="0 0 0" />
      <geometry>
        <mesh filename="../meshes/left_shoulder_yaw_link.STL" />
      </geometry>
      <material name="a">
        <color rgba="0.05 0.05 0.05 1" />
      </material>
    </visual>
    <!-- <collision>
      <origin xyz="0 0 0" rpy="0 0 0" />
      <geometry>
        <mesh filename="../meshes/left_shoulder_yaw_link.STL" />
      </geometry>
    </collision> -->
    <collision>
      <origin xyz="0 0 0" rpy="0 0 0" />
      <geometry>
        <cylinder radius="0.03968" length="0.14" />
      </geometry>
    </collision>
  </link>

  <joint name="left_shoulder_yaw_joint" type="revolute">
    <origin xyz="0 0 -0.13" rpy="0 0 0" />
    <parent link="left_shoulder_roll_link" />
    <child link="left_shoulder_yaw_link" />
    <axis xyz="0 0 1" />
    <limit lower="-1.9" upper="1.9" effort="100" velocity="14" />
  </joint>

  <link name="left_elbow_link">
    <inertial>
      <origin xyz="-4.1060603e-03 -2.2547010e-03 -5.4775265e-02" rpy="0 -1.57 0"/>
      <mass value="8.1901234e-01"/>
      <inertia
        ixx="1.5966173e-03" 
        ixy="7.9254545e-06" 
        ixz="1.3979156e-04" 
        iyy="1.5435859e-03" 
        iyz="9.5459458e-05" 
        izz="8.6127913e-04"/>
    </inertial>
    <visual>
      <origin xyz="0 0 0" rpy="0 -1.57 0" />
      <geometry>
        <mesh filename="../meshes/left_elbow_link.STL" />
      </geometry>
      <material name="a">
        <color rgba="0.05 0.05 0.05 1" />
      </material>
    </visual>
    <!-- <collision>
      <origin xyz="0 0 0" rpy="0 0 0" />
      <geometry>
        <mesh filename="../meshes/left_elbow_link.STL" />
      </geometry>
    </collision> -->
    <collision>
      <origin xyz="0 0 0" rpy="0 -1.57 0" />
      <geometry>
        <cylinder radius="0.043" length="0.079" />
      </geometry>
    </collision>
  </link>

  <joint name="left_elbow_joint" type="revolute">
    <origin xyz="0 0 -0.14" rpy="0  0 0" />
    <parent link="left_shoulder_yaw_link" />
    <child link="left_elbow_link" />
    <axis xyz="0 1 0" />
    <limit lower="-0.83" upper="1.57" effort="100" velocity="14" />
  </joint>

  <link name="left_wrist_yaw_link">
    <inertial>
      <origin xyz="0.0000000e+00 -1.0598513e-03 -5.6717954e-02" rpy="0 -1.57 0"/>
      <mass value="6.1426733e-01"/>
      <inertia
        ixx="4.7121608e-04" 
        ixy="0.0000000e+00" 
        ixz="0.0000000e+00" 
        iyy="4.7891195e-04" 
        iyz="-5.3981771e-06" 
        izz="3.4979129e-04"/>
    </inertial>
    <visual>
      <origin xyz="0 0 0" rpy="0 -1.57 0" />
      <geometry>
        <mesh filename="../meshes/left_wrist_yaw_link.STL" />
      </geometry>
      <material name="a">
        <color rgba="0.05 0.05 0.05 1" />
      </material>
    </visual>
    <!-- <collision>
      <origin xyz="0 0 0" rpy="0 0 0" />
      <geometry>
        <mesh filename="../meshes/left_wrist_yaw_link.STL" />
      </geometry>
    </collision> -->
    <collision>
      <origin xyz="0 0 0.01" rpy="0 0 0" />
      <geometry>
        <cylinder radius="0.035" length="0.07" />
      </geometry>
    </collision>
  </link>

  <joint name="left_wrist_yaw_joint" type="revolute">
    <origin xyz="0 0 -0.0955" rpy="0 1.57 0" />
    <parent link="left_elbow_link" />
    <child link="left_wrist_yaw_link" />
    <axis xyz="0 0 1" />
    <limit lower="-2.3" upper="2.3" effort="17" velocity="87" />
  </joint>

  <link name="left_wrist_pitch_link">
    <inertial>
      <origin xyz="1.1625996e-03 -2.8266432e-04 -5.7702211e-02" rpy="0 0 0"/>
      <mass value="7.3227634e-01"/>
      <inertia
        ixx="9.4034722e-04" 
        ixy="-2.4040905e-07" 
        ixz="7.9367732e-06" 
        iyy="7.0409858e-04" 
        iyz="9.9802725e-06" 
        izz="5.4229049e-04"/>
    </inertial>
    <visual>
      <origin xyz="0 0 0" rpy="0 -1.57 0" />
      <geometry>
        <mesh filename="../meshes/left_wrist_pitch_link.STL" />
      </geometry>
      <material name="a">
        <color rgba="0.05 0.05 0.05 1" />
      </material>
    </visual>
    <!-- <collision>
      <origin xyz="0 0 0" rpy="0 0 0" />
      <geometry>
        <mesh filename="../meshes/left_wrist_pitch_link.STL" />
      </geometry>
    </collision> -->
    <collision>
      <origin xyz="0 0 0.0" rpy="1.57 0 0" />
      <geometry>
        <cylinder radius="0.032" length="0.064" />
      </geometry>
    </collision>
  </link>

  <joint name="left_wrist_pitch_joint" type="revolute">
    <origin xyz="0 0 -0.0645" rpy="0 0 0" />
    <parent link="left_wrist_yaw_link" />
    <child link="left_wrist_pitch_link" />
    <axis xyz="0 1 0" />
    <limit lower="-1.2" upper="1.2" effort="17" velocity="87" />
  </joint>

  <link name="left_wrist_roll_link">
    <inertial>
      <origin xyz="0.01916043 -0.00000117 -0.02394803" rpy="0 0 0" />
      <mass value="0.0380932" />
      <inertia
        ixx="0.00001604"
        ixy="0.00000000"
        ixz="0.00000518"
        iyy="0.00002008"
        iyz="0.00000000"
        izz="0.00000997" />
    </inertial>
    <visual>
      <origin xyz="0 0 0" rpy="0 0 0" />
      <geometry>
        <mesh filename="../meshes/left_wrist_roll_link.STL" />
      </geometry>
      <material name="a">
        <color rgba="0.05 0.05 0.05 1" />
      </material>
    </visual>


    <visual>
      <origin xyz="0 0 0" rpy="0 1.5708 0"/> <!-- 绕Y轴旋转90度 -->
      <geometry>
        <mesh filename="../meshes/left_hand_link.STL" scale="1 1 1"/>
      </geometry>
      <material name="hand_material">
        <color rgba="0.05 0.05 0.05 1"/>
      </material>
    </visual>
    <collision>
      <origin xyz="0 0 0" rpy="0 1.5708 0"/>
      <geometry>
        <mesh filename="../meshes/left_hand_link.STL" scale="1 1 1"/>
      </geometry>
    </collision>


    <!-- <collision>
      <origin xyz="0 0 0" rpy="0 0 0" />
      <geometry>
        <mesh filename="../meshes/left_wrist_roll_link.STL" />
      </geometry>
    </collision> -->
    <collision>
      <origin xyz="0 0 0" rpy="0 1.57 0" />
      <geometry>
        <cylinder radius="0.035" length="0.054" />
      </geometry>
    </collision>
  </link>

  <joint name="left_wrist_roll_joint" type="revolute">
    <origin xyz="0 0 -0.068" rpy="0 0 0" />
    <parent link="left_wrist_pitch_link" />
    <child link="left_wrist_roll_link" />
    <axis xyz="1 0 0" />
    <limit lower="-1.2" upper="1.2" effort="17" velocity="87" />
  </joint>

  <link name="right_shoulder_pitch_link">
    <inertial>
      <origin xyz="-1.9833474e-02 -4.4431912e-02 5.5587489e-06" rpy="0 0 0" />
      <mass value="3.0353084e-01" />
      <inertia
        ixx="3.9643671e-04"
        ixy="-9.9021623e-05"
        ixz="-2.2578362e-09"
        iyy="1.6487917e-04"
        iyz="-2.0641827e-08"
        izz="3.8208098e-04" />
    </inertial>
    <visual>
      <origin xyz="0 0 0" rpy="0 0 0" />
      <geometry>
        <mesh filename="../meshes/right_shoulder_pitch_link.STL" />
      </geometry>
      <material name="a">
        <color rgba="0.05 0.05 0.05 1" />
      </material>
    </visual>
    <!-- <collision>
      <origin xyz="0 0 0" rpy="0 0 0" />
      <geometry>
        <mesh filename="../meshes/right_shoulder_pitch_link.STL" />
      </geometry>
    </collision> -->
    <collision>
      <origin xyz="0 -0.01 0" rpy="1.57 0 0" />
      <geometry>
        <cylinder radius="0.0244" length="0.018" />
      </geometry>
    </collision>
  </link>

  <joint name="right_shoulder_pitch_joint" type="revolute">
    <origin xyz="0 -0.12095 0.29712" rpy="0.17453 0 0" />
    <parent link="torso_link" />
    <child link="right_shoulder_pitch_link" />
    <axis xyz="0 1 0" />
    <limit lower="-3" upper="3" effort="100" velocity="14" />
  </joint>

  <link name="right_shoulder_roll_link">
    <inertial>
      <origin xyz="4.6571984e-03 -4.1483153e-05 -5.5419414e-02" rpy="0 0 0" />
      <mass value="1.6480208e+00" />
      <inertia
        ixx="5.2969146e-03"
        ixy="2.4490248e-06"
        ixz="-4.4137516e-04"
        iyy="5.2914384e-03"
        iyz="3.7517169e-06"
        izz="1.2519989e-03" />
    </inertial>
    <visual>
      <origin xyz="0 0 0" rpy="0 0 0" />
      <geometry>
        <mesh filename="../meshes/right_shoulder_roll_link.STL" />
      </geometry>
      <material name="a">
        <color rgba="0.05 0.05 0.05 1" />
      </material>
    </visual>
    <!-- <collision>
      <origin xyz="0 0 0" rpy="0 0 0" />
      <geometry>
        <mesh filename="../meshes/right_shoulder_roll_link.STL" />
      </geometry>
    </collision> -->
    <collision>
      <origin xyz="0 0 0" rpy="0 1.57 0" />
      <geometry>
        <cylinder radius="0.0447" length="0.1" />
      </geometry>
    </collision>
  </link>

  <joint name="right_shoulder_roll_joint" type="revolute">
    <origin  xyz="0 -0.0695 0" rpy="-0.17453 0 0" />
    <parent link="right_shoulder_pitch_link" />
    <child link="right_shoulder_roll_link" />
    <axis xyz="1 0 0" />
    <limit lower="-2.3" upper="0.12" effort="100" velocity="14" />
  </joint>

  <link name="right_shoulder_yaw_link">
    <inertial>
      <origin xyz="-8.6588430e-04 -2.7056640e-03 -1.1851792e-01" rpy="0 0 0"/>
      <mass value="1.0475841e+00"/>
      <inertia
        ixx="2.6989886e-03" 
        ixy="2.9564818e-06" 
        ixz="4.3512321e-05" 
        iyy="2.7131223e-03" 
        iyz="-6.1008586e-05" 
        izz="7.9314938e-04"/>
    </inertial>
    <visual>
      <origin xyz="0 0 0" rpy="0 0 0" />
      <geometry>
        <mesh filename="../meshes/right_shoulder_yaw_link.STL" />
      </geometry>
      <material name="a">
        <color rgba="0.05 0.05 0.05 1" />
      </material>
    </visual>
    <!-- <collision>
      <origin xyz="0 0 0" rpy="0 0 0" />
      <geometry>
        <mesh filename="../meshes/right_shoulder_yaw_link.STL" />
      </geometry>
    </collision> -->
    <collision>
      <origin xyz="0 0 0" rpy="0 0 0" />
      <geometry>
        <cylinder radius="0.03968" length="0.14" />
      </geometry>
    </collision>
  </link>

  <joint name="right_shoulder_yaw_joint" type="revolute">
    <origin  xyz="0 0 -0.13" rpy="0 0 0" />
    <parent link="right_shoulder_roll_link" />
    <child link="right_shoulder_yaw_link" />
    <axis xyz="0 0 1" />
    <limit lower="-1.9" upper="1.9" effort="100" velocity="14" />
  </joint>

  <link name="right_elbow_link">
    <inertial>
      <origin xyz="-4.1060960e-03 2.2047439e-03 -5.4775204e-02" rpy="0 0 0"/>
      <mass value="8.1901252e-01"/>
      <inertia
        ixx="1.5966211e-03" 
        ixy="-7.9253657e-06" 
        ixz="1.3979204e-04" 
        iyy="1.5435872e-03" 
        iyz="-9.5461542e-05" 
        izz="8.6127887e-04"/>
    </inertial>
    <visual>
      <origin xyz="0 0 0" rpy="0 0 0" />
      <geometry>
        <mesh filename="../meshes/right_elbow_link.STL" />
      </geometry>
      <material name="a">
        <color rgba="0.05 0.05 0.05 1" />
      </material>
    </visual>
    <!-- <collision>
      <origin xyz="0 0 0" rpy="0 0 0" />
      <geometry>
        <mesh filename="../meshes/right_elbow_link.STL" />
      </geometry>
    </collision> -->
    <collision>
      <origin xyz="0 0 0" rpy="1.57 0 0" />
      <geometry>
        <cylinder radius="0.043" length="0.079" />
      </geometry>
    </collision>
  </link>

  <joint name="right_elbow_joint" type="revolute">
    <origin xyz="0 0 -0.14" rpy="0 -1.57 0" />
    <parent link="right_shoulder_yaw_link" />
    <child link="right_elbow_link" />
    <axis xyz="0 1 0" />
    <limit lower="-0.83" upper="1.57" effort="100" velocity="14" />
  </joint>

  <link name="right_wrist_yaw_link">
    <inertial>
      <origin xyz="0.0000000e+00 1.0598507e-03 -5.6717954e-02" rpy="0 0 0"/>
      <mass value="6.1426734e-01"/>
      <inertia
        ixx="4.7121609e-04" 
        ixy="0.0000000e+00" 
        ixz="0.0000000e+00" 
        iyy="4.7891196e-04" 
        iyz="5.3981743e-06" 
        izz="3.4979130e-04"/>
    </inertial>
    <visual>
      <origin xyz="0 0 0" rpy="0 0 0" />
      <geometry>
        <mesh filename="../meshes/right_wrist_yaw_link.STL" />
      </geometry>
      <material name="a">
        <color rgba="0.05 0.05 0.05 1" />
      </material>
    </visual>
    <!-- <collision>
      <origin xyz="0 0 0" rpy="0 0 0" />
      <geometry>
        <mesh filename="../meshes/right_wrist_yaw_link.STL" />
      </geometry>
    </collision> -->
    <collision>
      <origin xyz="0 0 0.01" rpy="0 0 0" />
      <geometry>
        <cylinder radius="0.035" length="0.07" />
      </geometry>
    </collision>
  </link>

  <joint name="right_wrist_yaw_joint" type="revolute">
    <origin xyz="0 0 -0.0955" rpy="0 0 0" />
    <parent link="right_elbow_link" />
    <child link="right_wrist_yaw_link" />
    <axis xyz="0 0 1" />
    <limit lower="-2.3" upper="2.3" effort="17" velocity="87" />
  </joint>

  <link name="right_wrist_pitch_link">
    <inertial>
      <origin xyz="1.1625992e-03 2.8270210e-04 -5.7702211e-02" rpy="0 0 0"/>
      <mass value="7.3227634e-01"/>
      <inertia
        ixx="9.4034721e-04" 
        ixy="2.4089482e-07" 
        ixz="7.9368648e-06" 
        iyy="7.0409858e-04" 
        iyz="-9.9796755e-06" 
        izz="5.4229047e-04"/>
    </inertial>
    <visual>
      <origin xyz="0 0 0" rpy="0 0 0" />
      <geometry>
        <mesh filename="../meshes/right_wrist_pitch_link.STL" />
      </geometry>
      <material name="a">
        <color rgba="0.05 0.05 0.05 1" />
      </material>
    </visual>
    <!-- <collision>
      <origin xyz="0 0 0" rpy="0 0 0" />
      <geometry>
        <mesh filename="../meshes/right_wrist_pitch_link.STL" />
      </geometry>
    </collision> -->
    <collision>
      <origin xyz="0 0 0.0" rpy="1.57 0 0" />
      <geometry>
        <cylinder radius="0.032" length="0.064" />
      </geometry>
    </collision>
  </link>

  <joint name="right_wrist_pitch_joint" type="revolute">
    <origin xyz="0 0 -0.0645" rpy="0 0 0" />
    <parent link="right_wrist_yaw_link" />
    <child link="right_wrist_pitch_link" />
    <axis xyz="0 1 0" />
    <limit lower="-1.2" upper="1.2" effort="17" velocity="87" />
  </joint>

  <link name="right_wrist_roll_link">
    <inertial>
      <origin xyz="0.01916043 -0.00000117 -0.02394803" rpy="0 0 0" />
      <mass value="0.0380932" />
      <inertia
        ixx="0.00001604"
        ixy="0.00000000"
        ixz="0.00000518"
        iyy="0.00002008"
        iyz="0.00000000"
        izz="0.00000997" />
    </inertial>
    <visual>
      <origin xyz="0 0 0" rpy="0 0 0" />
      <geometry>
        <mesh filename="../meshes/right_wrist_roll_link.STL" />
      </geometry>
      <material name="a">
        <color rgba="0.05 0.05 0.05 1" />
      </material>


    </visual>

    <visual>
      <origin xyz="0 0 0" rpy="0 1.5708 0"/>  <!-- 绕Y轴旋转90°，让拳头朝前 -->
      <geometry>
        <mesh filename="../meshes/right_hand_link.STL" scale="1 1 1"/>
      </geometry>
      <material name="hand_material_right">
        <color rgba="0.05 0.05 0.05 1"/>
      </material>
    </visual>
    <collision>
      <origin xyz="0 0 0" rpy="0 1.5708 0"/>
      <geometry>
        <mesh filename="../meshes/right_hand_link.STL" scale="1 1 1"/>
      </geometry>
    </collision>

    <!-- <collision>
      <origin xyz="0 0 0" rpy="0 0 0" />
      <geometry>
        <mesh filename="../meshes/right_wrist_roll_link.STL" />
      </geometry>
    </collision> -->
    <collision>
      <origin xyz="0 0 0" rpy="0 1.57 0" />
      <geometry>
        <cylinder radius="0.035" length="0.054" />
      </geometry>
    </collision>

  </link>

  <joint name="right_wrist_roll_joint" type="revolute">
    <origin xyz="0 0 -0.068" rpy="0 0 0" />
    <parent link="right_wrist_pitch_link" />
    <child link="right_wrist_roll_link" />
    <axis xyz="1 0 0" />
    <limit lower="-1.2" upper="1.2" effort="17" velocity="87" />
  </joint>
</robot>
